<?xml version="1.0" encoding="UTF-8"?>
<!-- Generated by org.testng.reporters.JUnitXMLReporter -->
<testsuite hostname="Gal" name="Default test" tests="3" failures="1" timestamp="26 Nov 2017 18:50:22 GMT" time="51.226" errors="0">
  <testcase name="loginFailed1" time="8.51" classname="com.eply.tests.Login">
    <failure type="java.lang.AssertionError" message="expected [Sorry, either your username or password was incorrect.] but found [Sorry, either your username or password was incorrect.To continue you must update your password.]">
      <![CDATA[java.lang.AssertionError: expected [Sorry, either your username or password was incorrect.] but found [Sorry, either your username or password was incorrect.To continue you must update your password.]
	at org.testng.Assert.fail(Assert.java:94)
	at org.testng.Assert.failNotEquals(Assert.java:496)
	at org.testng.Assert.assertEquals(Assert.java:125)
	at org.testng.Assert.assertEquals(Assert.java:178)
	at org.testng.Assert.assertEquals(Assert.java:188)
	at com.eply.tests.Login.loginFailed1(Login.java:32)
	at sun.reflect.NativeMethodAccessorImpl.invoke0(Native Method)
	at sun.reflect.NativeMethodAccessorImpl.invoke(NativeMethodAccessorImpl.java:62)
	at sun.reflect.DelegatingMethodAccessorImpl.invoke(DelegatingMethodAccessorImpl.java:43)
	at java.lang.reflect.Method.invoke(Method.java:497)
	at org.testng.internal.MethodInvocationHelper.invokeMethod(MethodInvocationHelper.java:85)
	at org.testng.internal.Invoker.invokeMethod(Invoker.java:639)
	at org.testng.internal.Invoker.invokeTestMethod(Invoker.java:816)
	at org.testng.internal.Invoker.invokeTestMethods(Invoker.java:1124)
	at org.testng.internal.TestMethodWorker.invokeTestMethods(TestMethodWorker.java:125)
	at org.testng.internal.TestMethodWorker.run(TestMethodWorker.java:108)
	at org.testng.TestRunner.privateRun(TestRunner.java:774)
	at org.testng.TestRunner.run(TestRunner.java:624)
	at org.testng.SuiteRunner.runTest(SuiteRunner.java:359)
	at org.testng.SuiteRunner.runSequentially(SuiteRunner.java:354)
	at org.testng.SuiteRunner.privateRun(SuiteRunner.java:312)
	at org.testng.SuiteRunner.run(SuiteRunner.java:261)
	at org.testng.SuiteRunnerWorker.runSuite(SuiteRunnerWorker.java:52)
	at org.testng.SuiteRunnerWorker.run(SuiteRunnerWorker.java:86)
	at org.testng.TestNG.runSuitesSequentially(TestNG.java:1215)
	at org.testng.TestNG.runSuitesLocally(TestNG.java:1140)
	at org.testng.TestNG.run(TestNG.java:1048)
	at org.testng.remote.AbstractRemoteTestNG.run(AbstractRemoteTestNG.java:132)
	at org.testng.remote.RemoteTestNG.initAndRun(RemoteTestNG.java:236)
	at org.testng.remote.RemoteTestNG.main(RemoteTestNG.java:81)
]]>
    </failure>
  </testcase> <!-- loginFailed1 -->
  <testcase name="loginFailed2" time="7.965" classname="com.eply.tests.Login"/>
  <testcase name="loginSucceed" time="8.082" classname="com.eply.tests.Login"/>
</testsuite> <!-- Default test -->
